<?xml version="1.0" encoding="UTF-8"?>
<!-- Generated by org.testng.reporters.JUnitXMLReporter -->
<testsuite ignored="0" hostname="Yesh" failures="2" tests="2" name="Default test(failed)" time="6.262" errors="0" timestamp="2025-04-16T20:18:31 IST">
  <testcase classname="api.test.datadriventest" name="testPostUsers" time="0.0">
    <failure type="java.lang.RuntimeException" message="java.lang.ArrayIndexOutOfBoundsException: Index -1 out of bounds for length 3">
      <![CDATA[java.lang.RuntimeException: java.lang.ArrayIndexOutOfBoundsException: Index -1 out of bounds for length 3
at java.base/java.util.ArrayList.forEach(ArrayList.java:1596)
Caused by: java.lang.ArrayIndexOutOfBoundsException: Index -1 out of bounds for length 3
at api.utilities.DataProviderclass.getAllData(DataProviderclass.java:21)
... 25 more
... Removed 30 stack frames]]>
    </failure>
  </testcase> <!-- testPostUsers -->
  <testcase classname="api.test.datadriventest" name="testdeleteusers" time="5.03">
    <failure type="java.lang.AssertionError" message="expected [200] but found [404]">
      <![CDATA[java.lang.AssertionError: expected [200] but found [404]
at api.test.datadriventest.testdeleteusers(datadriventest.java:37)
at java.base/java.util.ArrayList.forEach(ArrayList.java:1596)
... Removed 32 stack frames]]>
    </failure>
  </testcase> <!-- testdeleteusers -->
</testsuite> <!-- Default test(failed) -->
